Workbook
Name _Hlk107062451: '3_非主結構碳足跡(施工&廢棄&修繕)'!$R$31

Sheet 工作表1
D1: 不分 | E1: 設計案 | F1: 基準案
B2: 地上樓地板面積 | C2: (m2) | G2: bim模型取得
B3: 地上樓層數(層) | G3: bim模型取得
B4: 地下樓地板面積 | C4: (m2) | G4: bim模型取得
B5: 地下樓層數(層) | G5: bim模型取得
B6: 建築延壽優惠係數LL | D6: 表10 | G6: 1、2：bim模型取得(待確認) 3、4：系統平台由使用者選擇
B7: 主地面層樓高BH | C7: (m) | G7: bim模型取得
B8: 內部隔間D0 | C8: (kg/㎡) | E8: 同基準案 | G8: 系統平台由使用者選擇 | H8: 少固定隔間之建築物：275 辦公、住宿、旅館、醫院(輕質)：300 社福機構等多隔間之建築物(磚牆/RC)：(350/375)
B9: W構造係數 | E9: 表2 | F9: 表7 | G9: 系統平台由使用者選擇 | H9: 基準案： 25F以下: 1.0(RC結構) 26F以上: 0.8(S結構)
B10: 地震利用途係數I | G10: 系統平台由使用者自己填寫(結構技師) | H10: 系統列出規範，使用者自行判斷
B11: 工址設計水平加速度反映譜係數SaD | G11: 系統平台由使用者自己填寫(結構技師)
B12: 結構系統地震力折減係數Fu | G12: 系統平台由使用者自己填寫(結構技師)
B13: 活載重L | C13: kgf/m2 | G13: 系統平台由使用者自己填寫(結構技師) | H13: https://law.moj.gov.tw/LawClass/LawSingle.aspx?pcode=D0070116&flno=17
B14: 靜力折減分析Rs | G14: 系統平台由使用者自己填寫(結構技師) | H14: 不需進行動力分析者，Rs = 0.95，反之Rs = 1.0。
B15: 21.平面形狀不規則修正係數 f1
B16: 22.平面長寬比修正係數 f2
B17: 23.平面出挑修正係數 f3
B18: 10.Br高爐水泥替代率
B19: 11.CSER水泥強度效益倍數
B20: 12.EBF舊建築再利用地上面積

Sheet 1_本案應揭露之碳足跡數據與碳足跡組成圖
B2: 表1
B3: 工程名稱 | J3: 需填入及確認的參數
B4: 所在位址
B5: 申請單位名稱 | D5: ○○工程顧問有限公司 | F5: 負責人
B6: 設計單位名稱 | D6: ○○建築師事務所 | F6: 建築師
B7: 施工單位名稱 | D7: ○○工程顧問
B8: 地上樓地板面積 | D8: 54270.09 | E8: (m2) | F8: 地上樓層數(層) | G8: 14
B9: 地下樓層數(層) | D9: 22698.87 | E9: (m2) | F9: 地下樓層數(層) | G9: 3
B10: 室內總樓地板面積 | D10: =D8+D9 -> 76968.96 | E10: (m2) | F10: 建築延壽優惠係數LL | G10: 0.2
B11: 全生命週期蘊含碳排TEC | D11: ='4_生命週期四階段蘊含碳排'!D15 -> 33931355 | E11: (kgCO2) | F11: 評估範疇蘊含碳排EEC | G11: ='4_生命週期四階段蘊含碳排'!D21 -> 21281188 | H11: (kgCO2)
B12: 蘊含碳排尺規指標ECIs | D12: ='4_生命週期四階段蘊含碳排'!D22 -> 392.13475 | E12: (kgCO2) | F12: 設計案蘊含碳排指標ECI | G12: ='4_生命週期四階段蘊含碳排'!D23 -> 326.77896 | H12: (kgCO2)
B13: 生命週期碳足跡(地上層) | C13: 生命週期階段 | D13: 碳足跡(kgCO2) | E13: 百分比
C14: 資材製造運輸階段 | D14: ='3_非主結構碳足跡(施工&廢棄&修繕)'!D30 -> 16583175 | E14: =D14/$D$18 -> 0.77924104
C15: 施工階段 | D15: ='3_非主結構碳足跡(施工&廢棄&修繕)'!F36 -> 833128.25 | E15: =D15/$D$18 -> 0.039148578
C16: 更新修繕階段 | D16: ='3_非主結構碳足跡(施工&廢棄&修繕)'!E17 -> 2358559.1 | E16: =D16/$D$18 -> 0.11082836
C17: 拆除廢棄階段 | D17: ='3_非主結構碳足跡(施工&廢棄&修繕)'!F40 -> 1506325.6 | E17: =D17/$D$18 -> 0.070782027
C18: 合計 | D18: =SUM(D14:D17) -> 21281188 | E18: =SUM(E14:E17) -> 1
B19: 分項碳足跡 | C19: 分項工程 | D19: 碳足跡(kgCO2) | E19: 百分比
C20: 主結構體工程 | D20: ='2_主結構碳排密度計算參數'!G22 -> 12554166 | E20: =D20/$D$28 -> 0.75704235
C21: 外牆外裝工程 | D21: ='3_非主結構碳足跡(施工&廢棄&修繕)'!D10 -> 1112683.9 | E21: =D21/$D$28 -> 0.067097156
C22: 外窗工程 | D22: ='3_非主結構碳足跡(施工&廢棄&修繕)'!D11 -> 234652.24 | E22: =D22/$D$28 -> 0.014150019
C23: 不透光帷幕牆工程 | D23: ='3_非主結構碳足跡(施工&廢棄&修繕)'!D12 -> 0 | E23: =D23/$D$28 -> 0
C24: 屋頂防水隔熱工程 | D24: ='3_非主結構碳足跡(施工&廢棄&修繕)'!D13 -> 310658 | E24: =D24/$D$28 -> 0.018733324
C25: 內隔間工程 | D25: ='3_非主結構碳足跡(施工&廢棄&修繕)'!D14 -> 153419.2 | E25: =D25/$D$28 -> 0.009251497
C26: 室內地坪工程 | D26: ='3_非主結構碳足跡(施工&廢棄&修繕)'!D15 -> 1797338.9 | E26: =D26/$D$28 -> 0.10838328
C27: 戶外地坪工程 | D27: ='3_非主結構碳足跡(施工&廢棄&修繕)'!D16 -> 420257 | E27: =D27/$D$28 -> 0.025342372
C28: 合計 | D28: =SUM(D20:D27) -> 16583175 | E28: 1
B29: 認證等級 | D29: □1+級 ▄1級 □2級 □3級 □4級 □5級 □6級 □7級

Sheet 2_主結構碳排密度計算參數
B1: 主結構碳排密度計算參數 | L1: 需填入及確認的參數
B2: 類別 | E2: 參數名稱 | G2: 設計案 | H2: 基準案 | I2: 備註
B3: 基本資料 | E3: 地上層樓地板面積AFu(㎡) | G3: ='1_本案應揭露之碳足跡數據與碳足跡組成圖'!D8 -> 54270.09 | L3: 21.平面形狀不規則修正係數 f1 | N3: 1.08
E4: 地下層樓地板面積AFb(㎡) | G4: ='1_本案應揭露之碳足跡數據與碳足跡組成圖'!D9 -> 22698.87 | L4: 22.平面長寬比修正係數 f2 | N4: 1
E5: 地上樓層數S(層) | G5: ='1_本案應揭露之碳足跡數據與碳足跡組成圖'!G8:H8 -> 14 | L5: 23.平面出挑修正係數 f3 | N5: 1
E6: 地下樓層數Sb(層) | G6: ='1_本案應揭露之碳足跡數據與碳足跡組成圖'!G9:H9 -> 3 | L6: 10.Br高爐水泥替代率 | N6: 0.15
E7: 主地面層樓高BH(m) | G7: 4.2 | L7: 11.CSER水泥強度效益倍數 | N7: 1.51
E8: 內部隔間D0(kg/㎡) | G8: 300 | H8: =G8 -> 300 | I8: 少固定隔間之建築物：275 辦公、住宿、旅館、醫院(輕質)：300 社福機構等多隔間之建築物(磚牆/RC)：(350/375) | L8: 12.EBF舊建築再利用地上面積 | N8: 0
E9: 4.W構造係數( P29) | G9: 1 | H9: 1 | I9: 基準案： 25F以下: 1.0(RC結構) 26F以上: 0.8(S結構)
B10: 結構計算報告參數 | E10: 地震利用途係數I | G10: 1 | I10: 依建築物耐震設計規範2.8節規定計算
E11: 工址設計水平加速度反映譜係數SaD | G11: 0.298 | I11: 依建築物耐震設計規範2.6節規定計算
E12: 結構系統地震力折減係數Fu | G12: 4 | I12: 依建築物耐震設計規範2.9節規定計算
E13: 活載重L | G13: 200 | I13: 視建築物用途依建築技術規則構造篇第17條決定
E14: 靜力折減分析Rs | G14: 1 | I14: 不需進行動力分析者，Rs = 0.95，反之Rs = 1.0。
B15: 結構設計參數 | E15: 跨距變化Sp | G15: =G28 -> 1.7226708 | H15: =IF(G5<=25,2,IF(G5>25,1.5)) -> 2 | I15: 基準案： 25F以下: 2.0 26F以上: 1.5
E16: 整體建築形狀係數F | G16: =N3*N4*N5 -> 1.08 | H16: =IF(G5<=25,1.1,IF(G5>25,1.05)) -> 1.1 | I16: 基準案： 25F以下: 1.1 26F以上: 1.05
E17: 高爐混凝土採用率BC | G17: =1-N6*0.3 -> 0.955 | H17: 1 | I17: BC僅對RC構造優惠計算，非RC構造時均設BC=1.0。
E18: 高性能混凝土採用率HC | G18: =1-N7*0.05 -> 0.9245 | H18: 1 | I18: HC僅對RC、S構造優惠計算，輕鋼構與木構造時均設HC=1.0。
E19: 舊建築再利用率RN | G19: =(G3-N8)/G3 -> 1 | H19: 1
G21: 設計案 | H21: 基準案 | J21: 檢討BC,HC,減碳量
B22: CFs=Cu*BC*HC*RN | G22: =G25*G17*G18*G19 -> 12554166 | H22: =H25*H17*H18*H19 -> 15620641 | I22: =G22-H22 -> -3066475.4 | J22: =G25*G17*H18*G19 -> 13579412 | K22: =$H$22-J22 -> 2041229.8 | L22: BC貢獻 | M22: =($I$22-$L$24)*K22/($K$23+$K$22) -> -826777.79
B23: CFs'=330*AFb+45.5*(AFu+AFb) | G23: =330*G4+45.5*(G3+G4) -> 10992715 | H23: =330*G4+45.5*(G3+G4) -> 10992715 | J23: =G25*H17*G18*G19 -> 13145724 | K23: =$H$22-J23 -> 2474917.9 | L23: HC貢獻 | M23: =($I$22-$L$24)*K23/($K$23+$K$22) -> -1002438.4
J24: Sp+F貢獻=ΔCu*BC*HC*RN | L24: =(G25-H25)*G17*G18*G19 -> -1237259.3
C25: Cu=Afu*C*W | G25: =$G$3*G27*G9 -> 14219279 | H25: =$G$3*H27*H9 -> 15620641
D26: C=(224+4.11*(S-10)+300*(I*SaD/Fu-0.192)+68.74*(Sp-1.0)+0.17*(D0-300)+0.13*(L-300)+1.05*(BH-3.5))*Rs*F
G27: =(224+4.11*($G$5-10)+300*($G$10*$G$11/$G$12-0.192)+68.74*(G15-1) +0.17 *($G$8-300)+0.13*($G$13-300)+1.05*($G$7-3.5)) *$G$14*G16 -> 262.0095 | H27: =(224+4.11*($G$5-10)+300*($G$10*$G$11/$G$12-0.192)+68.74*(H15-1) +0.17 *($G$8-300)+0.13*($G$13-300)+1.05*($G$7-3.5)) *$G$14*H16 -> 287.8315
D28: Sp=(ax*Bx*+ay*By)/((Bx+By) | G28: =(L30*J30+L31*J31)/(J30+J31) -> 1.7226708 | H28: =H15 -> 2
I30: Bx= | J30: 27.05 | K30: ax= | L30: =9.7/7.65 -> 1.2679739
I31: By= | J31: =8.5*3+7.3*2+4.25 -> 44.35 | K31: ay= | L31: =8.5/4.25 -> 2

Sheet 3_非主結構碳足跡(施工&廢棄&修繕)
J1: 需填入及確認的參數
B3: 地上層建築資材CFs/CFns總覽
J4: 1. 外牆外裝Cfow | R4: 8.舊建材再利用減碳量
B6: 構造部位 | D6: 設計案 | J6: 設計案(單位: kgCO2) | M6: CFow新建碳排 | O6: Cfow*修繕更新碳排 | R6: 設計案(單位: kgCO2) | T6: 再生建材減碳量
B7: (單位: kgCO2) | D7: CFum | E7: CFrm | F7: CFum+CFrm | G7: 各部位建材 | J7: 編號 | K7: 構造名稱 | L7: 構造面積(㎡) | M7: 單位碳排 | N7: 新建碳排 | O7: 更新單位碳排* | P7: 修繕碳排 | R7: 編號 | S7: 建材名稱 | T7: 單位量Rk(單位.) | U7: 舊建材再利用碳排標準RMk(kgCO2/單位) | V7: 減碳量
D8: 新建資材 | E8: 更新資材 | F8: 合計 | G8: 碳排組成 | J8: Fow1 | K8: RC外牆貼磁磚(9.05+21.2) | L8: 31903.6 | M8: 30.25 | N8: =L8*M8 -> 965083.9 | O8: =21.2*1 -> 21.2 | P8: =O8*L8 -> 676356.32 | R8: CFw1 | V8: =T8*U8 -> 0
B9: 主結構體CFs | D9: ='2_主結構碳排密度計算參數'!G22 -> 12554166 | F9: =D9+E9 -> 12554166 | G9: =F9/($F$17+$F$9) -> 0.66277806 | J9: Fow2 | K9: RC牆塗料外裝(9.05+5.71) | L9: 10000 | M9: 14.76 | N9: =L9*M9 -> 147600 | O9: =5.71*3 -> 17.13 | P9: =O9*L9 -> 171300 | R9: CFw2 | V9: =T9*U9 -> 0
B10: 非主結構CFns | C10: 外牆外裝CFow | D10: =N11 -> 1112683.9 | E10: =P11 -> 847656.32 | F10: =D10+E10 -> 1960340.2 | G10: =F10/($F$17+$F$9) -> 0.10349317 | H10: =F10-F20 -> -195600 | J10: Fow3 | R10: CFw3 | V10: =T10*U10 -> 0
C11: 外窗CFw | D11: =N25 -> 234652.24 | E11: =P25 -> 0 | F11: =D11+E11 -> 234652.24 | G11: =F11/($F$17+$F$9) -> 0.012388108 | H11: =F11-F21 -> 0 | K11: Σ | L11: =SUM(L8:L10) -> 41903.6 | N11: =SUM(N8:N10) -> 1112683.9 | P11: =SUM(P8:P10) -> 847656.32 | V11: =SUM(V8:V10) -> 0
C12: 不透光帷幕牆CFcw | D12: =N40 -> 0 | E12: =P40 -> 0 | F12: =D12+E12 -> 0 | G12: =F12/($F$17+$F$9) -> 0 | H12: =F12-F22 -> 0 | J12: 基準案 (單位:kg) | M12: CFiw新建碳排(kg) | O12: CFiw*修繕更新碳排(kg) | R12: 註1：RMk為採用舊建材、舊構件的減碳量，由申請者依ABRI 碳足跡資料庫標準換算認定為該建材、構件的減碳量 註2：若無舊建材再利用則不必檢討
C13: 內隔間CFiw | D13: =N52 -> 310658 | E13: =P52 -> 0 | F13: =D13+E13 -> 310658 | G13: =F13/($F$17+$F$9) -> 0.016400716 | H13: =F13-F23 -> -206300.25 | J13: 編號 | K13: 構造名稱 | L13: 構造面積(㎡) | M13: 單位碳排 | N13: 新建碳排 | O13: 單位碳排* | P13: 修繕碳排
C14: 屋頂防水隔熱CFr | D14: =N63 -> 153419.2 | E14: =P63 -> 767095.98 | F14: =D14+E14 -> 920515.17 | G14: =F14/($F$17+$F$9) -> 0.048597196 | H14: =F14-F24 -> 0 | J14: Fow1 | K14: RC外牆貼磁磚 | L14: =L11 -> 41903.6 | M14: 30.25 | N14: =L14*M14 -> 1267583.9 | O14: 21.2 | P14: =O14*L14 -> 888356.32 | Q14: =N11-N15 -> -154900
C15: 室內地坪CFf | D15: =N73 -> 1797338.9 | E15: =P73 -> 547780.12 | F15: =D15+E15 -> 2345119.1 | G15: =F15/($F$17+$F$9) -> 0.12380699 | H15: =F15-F25 -> 0 | K15: Σ | L15: =L14 -> 41903.6 | M15: Σ | N15: =N14 -> 1267583.9 | P15: =P14 -> 888356.32
C16: 戶外地坪CFp | D16: =N87 -> 420257 | E16: =P87 -> 196026.67 | F16: =D16+E16 -> 616283.67 | G16: =F16/($F$17+$F$9) -> 0.032535757 | H16: =F16-F26 -> 67489.116 | J16: *註：貼磁磚外牆表層更新1次；塗料外裝更新3次，詳見附錄二表1
C17: 非主結構資材CFns小計 | D17: =SUM(D10:D16) -> 4029009.3 | E17: =SUM(E10:E16) -> 2358559.1 | F17: =SUM(F10:F16) -> 6387568.4 | G17: =F17/$F$17 -> 1 | R17: 9.低碳循環建材減碳量
B18: 構造部位 | D18: 基準案 | J18: 2.外窗CFw | R18: 設計案(單位: kgCO2) | T18: 再生建材減碳量
B19: 主結構體CFs | D19: ='2_主結構碳排密度計算參數'!H22 -> 15620641 | F19: =D19+E19 -> 15620641 | G19: =F19/$F$27 -> 0.69914096 | J19: 設計案(單位: kgCO2) | M19: CFw新建碳排 | O19: CFw*修繕更新碳排 | R19: 編號 | S19: 建材名稱 | T19: 單位量Uk(單位.) | U19: 再生建材碳排標準CMk(kgCO2/單位) | V19: 減碳量
B20: 非主結構CFns | C20: 外牆外裝CFow | D20: =N15 -> 1267583.9 | E20: =P15 -> 888356.32 | F20: =D20+E20 -> 2155940.2 | G20: =F20/$F$27 -> 0.096494508 | J20: 編號 | K20: 構造名稱 | L20: 構造面積(㎡) | M20: 單位碳排 | N20: 新建碳排 | O20: 單位碳排* | P20: 修繕碳排 | R20: CFw1 | V20: =T20*U20 -> 0
C21: 外窗CFw | D21: =N32 -> 234652.24 | E21: =P32 -> 0 | F21: =D21+E21 -> 234652.24 | G21: =F21/$F$27 -> 0.010502449 | J21: CFw1 | K21: 鋁框+5+5mm玻璃 | L21: 2477.48 | M21: 45.45 | N21: =L21*M21 -> 112601.47 | O21: 0 | P21: =O21*L21 -> 0 | R21: CFw2 | V21: =T21*U21 -> 0
C22: 帷幕牆CFcw | D22: =N44 -> 0 | F22: =D22+E22 -> 0 | G22: =F22/$F$27 -> 0 | J22: CFw2 | K22: 鋁框+6+6mm玻璃 | L22: 1599.36 | M22: 49.55 | N22: =L22*M22 -> 79248.288 | O22: 0 | P22: =O22*L22 -> 0 | R22: CFw3 | V22: =T22*U22 -> 0
C23: 內隔間CFiw | D23: =N56 -> 516958.25 | E23: =P56 -> 0 | F23: =D23+E23 -> 516958.25 | G23: =F23/$F$27 -> 0.023137762 | J23: CFw3 | K23: 鋁框+清10mm | L23: 494.07 | M23: 45.45 | N23: =L23*M23 -> 22455.482 | O23: 0 | P23: =O23*L23 -> 0 | V23: =SUM(V20:V22) -> 0
C24: 屋頂防水隔熱CFr | D24: =N63 -> 153419.2 | E24: =P63 -> 767095.98 | F24: =D24+E24 -> 920515.17 | G24: =F24/$F$27 -> 0.041199964 | J24: CFw4 | K24: 鋁框+清5mm | L24: 578.04 | M24: 35.2 | N24: =L24*M24 -> 20347.008 | O24: 0 | P24: =O24*L24 -> 0 | R24: 註1：LCRk為低碳循環減碳量，為具有實質減碳效益的再利用、再循環、再生建材或因製程改善而有實質減碳效益且經 ABRI 指定評定機構認證通過之建材減碳量。 註2：若無低碳循環建材不必檢討
C25: 室內地坪CFf | D25: =N77 -> 1797338.9 | E25: =P77 -> 547780.12 | F25: =D25+E25 -> 2345119.1 | G25: =F25/$F$27 -> 0.10496168 | K25: Σ | L25: =SUM(L21:L24) -> 5148.95 | N25: =SUM(N21:N24) -> 234652.24 | P25: =SUM(P21:P24) -> 0
C26: 戶外地坪CFp | D26: =N91 -> 386512.44 | E26: =P91 -> 162282.12 | F26: =D26+E26 -> 548794.55 | G26: =F26/$F$27 -> 0.024562676 | J26: 基準案(單位: kgCO2) | M26: CFw新建碳排 | O26: CFw*修繕更新碳排
C27: 非主結構資材CFns小計 | D27: =SUM(D20:D26) -> 4356465 | E27: =SUM(E19:E26) -> 2365514.5 | F27: =SUM(F19:F26) -> 22342621 | G27: =F27/$F$27 -> 1 | J27: 編號 | K27: 構造名稱 | L27: 構造面積(㎡) | M27: 單位碳排 | N27: 新建碳排 | O27: 單位碳排* | P27: 修繕碳排
J28: CFw1 | K28: 鋁框+5+5mm玻璃 | L28: 2477.48 | M28: 45.45 | N28: =L28*M28 -> 112601.47 | O28: 0 | P28: =O28*L28 -> 0 | R28: 10.低碳工法應用
B29: CFum=CFs+CFns | D29: 設計案CFum | E29: 基準案CFum | J29: CFw2 | K29: 鋁框+6+6mm玻璃 | L29: 1599.36 | M29: 49.55 | N29: =L29*M29 -> 79248.288 | O29: 0 | P29: =O29*L29 -> 0 | R29: 設計案低碳工法減碳量(單位: kgCO2)
D30: =D9+D17 -> 16583175 | E30: =D19+D27 -> 19977106 | J30: CFw3 | K30: 鋁框+清10mm | L30: 494.07 | M30: 45.45 | N30: =L30*M30 -> 22455.482 | O30: 0 | P30: =O30*L30 -> 0 | R30: Lccm= | S30: 0
J31: CFw4 | K31: 鋁框+清5mm | L31: 578.04 | M31: 35.2 | N31: =L31*M31 -> 20347.008 | O31: 0 | P31: =O31*L31 -> 0 | R31: 註1：LCCm: m低碳工法減碳量(kgCO2)，為具有實質減碳效益且經 ABRI 指定評定機構認證通過的工法減碳量。減碳量以正值標示之，由 ABRI 另立低碳工法認定辦法，由申請方向ABRI 指定評定機構申請認定之 ，請檢附證明文件 註2：若無採用低碳工法不必檢討
B32: 參數名稱 | D32: 設計案 | E32: 基準案 | F32: 備註 | J32: Σ | L32: =SUM(L28:L31) -> 5148.95 | N32: =SUM(N28:N31) -> 234652.24 | P32: =SUM(P28:P31) -> 0
B33: 新建與拆除廢棄物量密度Wd | D33: 390 | E33: 390 | F33: 新建與拆除廢棄物量密度（kg/m2），取自表7 | J33: *註：僅木窗框更新次數2，單位碳排5.22，其餘更新次數0，無修繕碳排，詳見附錄二表2
B35: 3.施工 | F35: 設計案 | G35: 基準案 | J35: 3. 不透光帷幕牆CFcw
B36: CFc =（0.14+ 0.95×S）× AFu ×（1.0 + CFrm/ CFum） | F36: =(0.14+0.95*'2_主結構碳排密度計算參數'!G5)*'2_主結構碳排密度計算參數'!G3*(1+E17/D30) -> 833128.25 | G36: =F36 -> 833128.25 | H36: 地上層 | J36: 設計案(單位: kgCO2) | M36: CFcw新建碳排 | O36: CFcw*修繕更新碳排
B37: CFc'=（0.14+ 2.14×Sb）× AF | F37: =(0.14+2.14*'2_主結構碳排密度計算參數'!$G$6)*'1_本案應揭露之碳足跡數據與碳足跡組成圖'!$D$10 -> 504916.38 | G37: =F37 -> 504916.38 | H37: 地下層 | J37: 編號 | K37: 構造名稱 | L37: 構造面積(㎡) | M37: 單位碳排 | N37: 新建碳排 | O37: 單位碳排* | P37: 修繕碳排
J38: CFcw1 | K38: 金屬板面內襯隔熱材帷幕牆 | L38: 0 | N38: =L38*M38 -> 0 | O38: 0 | P38: =O38*L38 -> 0
B39: 4.拆除廢棄 | J39: CFcw2 | K39: 石材版內襯隔熱材帷幕牆 | L39: 0 | N39: =L39*M39 -> 0 | O39: 0 | P39: =O39*L39 -> 0
B40: CFdw＝（CFd＋CFwa）×（1.0＋CFrm/CFum） | F40: =(F41+F42)*(1+E17/D30) -> 1506325.6 | G40: =F40 -> 1506325.6 | H40: 地上層 | J40: Σ | L40: =SUM(L38:L39) -> 0 | N40: =SUM(N38:N39) -> 0 | P40: =SUM(P38:P39) -> 0
D41: CFd= （0.06×S +2.01）× Afu | F41: =(0.06*'2_主結構碳排密度計算參數'!$G$5+2.01)*'2_主結構碳排密度計算參數'!$G$3 -> 154669.76 | G41: =(0.06*'2_主結構碳排密度計算參數'!$G$5+2.01)*'2_主結構碳排密度計算參數'!$G$3 -> 154669.76 | J41: 基準案(單位: kgCO2) | M41: CFcw新建碳排 | O41: CFcw*修繕更新碳排
D42: CFwa= 0.055 × Wd × Afu | F42: =0.055*D33*'2_主結構碳排密度計算參數'!$G$3 -> 1164093.4 | G42: =0.055*E33*'2_主結構碳排密度計算參數'!$G$3 -> 1164093.4 | J42: 編號 | K42: 構造名稱 | L42: 構造面積(㎡) | M42: 單位碳排 | N42: 新建碳排 | O42: 單位碳排* | P42: 修繕碳排
B43: CFdw’＝CFd’＋CFwa’ | F43: =F44+F45 -> 1152535.1 | G43: =G44+G45 -> 1152535.1 | H43: 地下層 | J43: CFcw1 | K43: 傳統15cm RC外牆 | L43: =L40 -> 0 | M43: 73.67 | N43: =L43*M43 -> 0 | O43: 0 | P43: =O43*L43 -> 0
...

Sheet 4_生命週期四階段蘊含碳排
B1: 以下數值會自動帶入，請確認是否正確！
B2: 生命週期四階段蘊含碳排 | J2: 施工延壽優惠LL
B3: 邊界 | C3: 項目 | D3: 設計案 | F3: 基準案 | H3: 減碳量ΔCF (kgCO2) | J3: 說明：統包商若為五年內行政院、直轄市工程品質金質獎之優良營造廠施工(另附證明文件)，可得整體建築延壽優惠係數LL優惠為0.2。 | O3: 大項 | P3: 延壽條件LLi | Q3: 建築延壽優惠係數LL*1 | R3: 檢核
D4: 碳排量(kgCO2) | E4: 占比 | F4: 碳排量(kgCO2) | G4: 占比 | O4: 耐久設計 | P4: 1.RC柱樑與RC樓板兩者均完全無埋設管線者 | Q4: 0.2 | R4: □
B5: 地下層 | C5: 地下層資材CFs’ | D5: ='2_主結構碳排密度計算參數'!G23 -> 10992715 | F5: ='2_主結構碳排密度計算參數'!H23 -> 10992715 | J5: LL= | K5: ='1_本案應揭露之碳足跡數據與碳足跡組成圖'!G10 -> 0.2 | P5: 2.RC柱樑與RC樓板兩者之一完全無埋設管線者 | Q5: 0.1 | R5: □
C6: 地下施工CFc’ | D6: ='3_非主結構碳足跡(施工&廢棄&修繕)'!F37 -> 504916.38 | F6: ='3_非主結構碳足跡(施工&廢棄&修繕)'!G37 -> 504916.38 | O6: 高品質施工 | P6: 3.獲ISO14000認證或五年內獲行政院、直轄市工程品質金質獎之優良營造廠者 | Q6: 0.2 | R6: ■
C7: 地下拆除廢棄CFdw’ | D7: ='3_非主結構碳足跡(施工&廢棄&修繕)'!F43 -> 1152535.1 | F7: ='3_非主結構碳足跡(施工&廢棄&修繕)'!G43 -> 1152535.1 | P7: 4.五年內獲各縣市政府工程品質金質獎或獲國家建設金質獎之優良營造廠者 | Q7: 0.1 | R7: □
C8: 地下層碳排小計 | D8: =SUM(D5:D7) -> 12650166 | F8: =SUM(F5:F7) -> 12650166 | O8: LL= | Q8: 0.2
B9: 地上層EEC | C9: 資材製造運輸CFum | D9: ='3_非主結構碳足跡(施工&廢棄&修繕)'!D30 -> 16583175 | E9: =D9/$D$13 -> 0.77924104 | F9: ='3_非主結構碳足跡(施工&廢棄&修繕)'!E30 -> 19977106 | G9: 0.821 | H9: =D9-F9 -> -3393931.1 | O9: *1:1.2.兩項之一與3.4.兩項之一可累加計算，3.4.兩項不能累加計算
C10: 更新修繕CFrm | D10: ='3_非主結構碳足跡(施工&廢棄&修繕)'!E17 -> 2358559.1 | E10: =D10/$D$13 -> 0.11082836 | F10: ='3_非主結構碳足跡(施工&廢棄&修繕)'!E27 -> 2365514.5 | G10: 0.1093 | H10: =D10-F10 -> -6955.442
C11: 施工CFc | D11: ='3_非主結構碳足跡(施工&廢棄&修繕)'!F36 -> 833128.25 | E11: =D11/$D$13 -> 0.039148578 | F11: ='3_非主結構碳足跡(施工&廢棄&修繕)'!G36 -> 833128.25 | G11: 0.021
C12: 拆除廢棄CFdw | D12: ='3_非主結構碳足跡(施工&廢棄&修繕)'!F40 -> 1506325.6 | E12: =D12/$D$13 -> 0.070782027 | F12: ='3_非主結構碳足跡(施工&廢棄&修繕)'!G40 -> 1506325.6 | G12: 0.0487
C13: 地上層蘊含碳排EEC | D13: =SUM(D9:D12) -> 21281188 | E13: =SUM(E9:E12) -> 1 | F13: =SUM(F9:F12) -> 24682075 | G13: =SUM(G9:G12) -> 1 | H13: =D13-F13 -> -3400886.6
B14: 蘊含碳排尺規指標ECIs | D14: =D22 -> 392.13475 | F14: =F22 -> 454.8007
B15: 全生命週期碳排TEC | D15: =D8+D13 -> 33931355 | E15: (kg CO2) | F15: =F8+F13 -> 37332241 | G15: (kg CO2)
B18: TEC=CFum + CFs’ + CFrm + CFc+ CFc’ + CFdw+ CFdw’
D19: 設計案 | F19: 基準案
C20: TEC= | D20: =SUM(D5:D7,D9:D12) -> 33931355 | F20: =SUM(F5:F7,F9:F12) -> 37332241
B21: EEC=CFum + CFrm + CFc + CFdw | D21: =D13 -> 21281188 | F21: =F13 -> 24682075 | N21: 等級 | O21: 減碳率CFR間距
B22: ECIs = EEC / Afu | D22: =D13/'1_本案應揭露之碳足跡數據與碳足跡組成圖'!$D$8 -> 392.13475 | F22: =F13/'1_本案應揭露之碳足跡數據與碳足跡組成圖'!$D$8 -> 454.8007 | J22: ECIs= | K22: =D22 -> 392.13475 | N22: 1+級 | O22: 20%＜CFR
B23: ECI = ECIs /(1.0+LL) | D23: =D22/(1+K5) -> 326.77896 | J23: 1~1+ | K23: 0.8 | L23: =$K$22*K23 -> 313.7078 | N23: 1級 | O23: 16％＜CFR≦20％
K24: 0.84 | L24: =$K$22*K24 -> 329.39319 | N24: 2級 | O24: 12％＜CFR≦16％
K25: 0.88 | L25: =$K$22*K25 -> 345.07858 | N25: 3級 | O25: 8％＜CFR≦12％
B26: ΔCF＝ (CFsc– CFs) ＋ (ΔCFow＋ΔCFw＋ΔCFcw＋ΔCFiw＋ΔCFf＋ΔCFp)–ΣCMk ×Uk–ΣLCCm | K26: 0.92 | L26: =$K$22*K26 -> 360.76397 | N26: 4級 | O26: 3％＜CFR≦8％
D27: ΔCFs＝CFs-CFSc | E27: ='3_非主結構碳足跡(施工&廢棄&修繕)'!F9-'3_非主結構碳足跡(施工&廢棄&修繕)'!F19 -> -3066475.4 | K27: 0.97 | L27: =$K$22*K27 -> 380.37071 | N27: 5級 | O27: -10％＜CFR≦3％
D28: ΔCFow＝ΣΔFowj×Aowj= | E28: ='3_非主結構碳足跡(施工&廢棄&修繕)'!F10-'3_非主結構碳足跡(施工&廢棄&修繕)'!F20 -> -195600 | K28: 1.1 | L28: =$K$22*K28 -> 431.34823 | N28: 6級 | O28: -20％＜CFR≦-10％
D29: ΔCFw＝ΣΔFwj×Awj= | E29: ='3_非主結構碳足跡(施工&廢棄&修繕)'!F11-'3_非主結構碳足跡(施工&廢棄&修繕)'!F21 -> 0 | K29: 1.2 | L29: =$K$22*K29 -> 470.5617 | N29: 7級 | O29: CFR≦-20％
D30: ΔCFcw＝ΣΔFcwj×Acwj= | E30: ='3_非主結構碳足跡(施工&廢棄&修繕)'!F12-'3_非主結構碳足跡(施工&廢棄&修繕)'!F22 -> 0
D31: ΔCFiw＝ΣΔFiwj×Aiwj= | E31: ='3_非主結構碳足跡(施工&廢棄&修繕)'!F13-'3_非主結構碳足跡(施工&廢棄&修繕)'!F23 -> -206300.25
D32: ΔCFf＝ΣΔFfj×Afj = | E32: ='3_非主結構碳足跡(施工&廢棄&修繕)'!F15-'3_非主結構碳足跡(施工&廢棄&修繕)'!F25 -> 0
D33: ΔCFp=ΣΔFpj×Apj= | E33: ='3_非主結構碳足跡(施工&廢棄&修繕)'!F16-'3_非主結構碳足跡(施工&廢棄&修繕)'!F26 -> 67489.116
D34: ΔCF＝ | E34: =E27+SUM(E28:E33) -> -3400886.6
B35: CFR＝ΔCF×(1.0+LL)/ EEC | E35: =E34*(1+K5)/D21 -> -0.19176861

Sheet 5_各項減碳設計ΔCF貢獻度分析
B1: 各項減碳設計ΔCF貢獻度分析 | E1: 以下數值會自動帶入，請確認是否正確！若有其他減碳量請自行輸入
B2: 地上蘊含 | D2: 設計案EEC | E2: ='4_生命週期四階段蘊含碳排'!D13 -> 21281188 | F2: 地上總樓地板面積AFu= | H2: ='1_本案應揭露之碳足跡數據與碳足跡組成圖'!D8 -> 54270.09
B3: 碳排(kgCO2) | D3: 基準案EEC* | E3: ='4_生命週期四階段蘊含碳排'!F13 -> 24682075 | F3: 碳排密度ECI=EEC/AFu= | H3: =E2/H2 -> 392.13475
B4: 減碳參數 | C4: 減碳設計 | G4: 減碳量 | I4: 減碳比
G5: ΔCF (kgCO2)
B6: CFs-1 | C6: 跨距比Sp檢討1.72優於標準2.0水準，建築形狀方整形狀係數1.08優於標準1.1水準 | G6: ='2_主結構碳排密度計算參數'!L24 -> -1237259.3 | I6: =G6/$E$3 -> -0.050127846
B7: CFs-2 | C7: 主結構體採用15%高爐混凝土 | G7: ='2_主結構碳排密度計算參數'!M22 -> -826777.79 | I7: =G7/$E$3 -> -0.033497094
B8: CFs-3 | C8: 主結構體採用高性能混凝土設計CSER=1.51 | G8: ='2_主結構碳排密度計算參數'!M23 -> -1002438.4 | I8: =G8/$E$3 -> -0.040614024
B9: CFiw | C9: 內隔間全面採用灌漿牆取代磚牆 | G9: ='3_非主結構碳足跡(施工&廢棄&修繕)'!F13-'3_非主結構碳足跡(施工&廢棄&修繕)'!F23 -> -206300.25 | I9: =G9/$E$3 -> -0.0083583027
B10: Cfow | C10: 外牆外裝部分採塗料取代貼磁磚 | G10: ='4_生命週期四階段蘊含碳排'!E28 -> -195600 | I10: =G10/$E$3 -> -0.0079247795
B11: CFp | C11: 戶外地坪採用RC地坪+連鎖磚設計增碳 | G11: ='3_非主結構碳足跡(施工&廢棄&修繕)'!F16-'3_非主結構碳足跡(施工&廢棄&修繕)'!F26 -> 67489.116 | I11: =G11/$E$3 -> 0.0027343372
C12: 設計技術減碳量合計 | G12: =SUM(G6:H11) -> -3400886.6 | I12: =G12/$E$3 -> -0.13778771
B13: LL | C13: 良好施工品質提供建築延壽 | G13: =D18 -> -680177.31 | I13: -0.0297
C14: 設計及施工減碳量合計 | G14: =G12+G13 -> -4081063.9 | I14: =I12+I13 -> -0.16748771
B16: ΔCF= | C16: =G12 -> -3400886.6
B17: ΔCFLL=設計技術減碳量合計-ΔCF×(1.0+LL)= | F17: =C16*(1+'4_生命週期四階段蘊含碳排'!K5) -> -4081063.9
B18: LL延壽相當減碳量= | D18: =F17-C16 -> -680177.31

Sheet 報告書圖表
B1: 以下數值會自動帶入，請確認是否正確！
B2: kgCO2 | C2: 新建 | D2: 修繕
B3: 主結構體 | C3: ='3_非主結構碳足跡(施工&廢棄&修繕)'!D9 -> 12554166 | D3: ='3_非主結構碳足跡(施工&廢棄&修繕)'!E9 -> 0 | E3: =C3/(C3+D3) -> 1 | F3: =D3/(C3+D3) -> 0
B4: 外牆外裝 | C4: ='3_非主結構碳足跡(施工&廢棄&修繕)'!D10 -> 1112683.9 | D4: ='3_非主結構碳足跡(施工&廢棄&修繕)'!E10 -> 847656.32 | E4: =C4/(C4+D4) -> 0.56759734 | F4: =D4/(C4+D4) -> 0.43240266
B5: 外窗 | C5: ='3_非主結構碳足跡(施工&廢棄&修繕)'!D11 -> 234652.24 | D5: ='3_非主結構碳足跡(施工&廢棄&修繕)'!E11 -> 0 | E5: =C5/(C5+D5) -> 1 | F5: =D5/(C5+D5) -> 0
B6: 不透光帷幕牆 | C6: ='3_非主結構碳足跡(施工&廢棄&修繕)'!D12 -> 0 | D6: ='3_非主結構碳足跡(施工&廢棄&修繕)'!E12 -> 0 | E6: =IF(C6="0",0,IF(C6>0,C6/(C6+D6))*FALSE) -> 0 | F6: =IF(D6="0",0,IF(C6>0,C6/(C6+D6))*FALSE) -> 0
B7: 內隔間 | C7: ='3_非主結構碳足跡(施工&廢棄&修繕)'!D13 -> 310658 | D7: ='3_非主結構碳足跡(施工&廢棄&修繕)'!E13 -> 0 | E7: =C7/(C7+D7) -> 1 | F7: =D7/(C7+D7) -> 0
B8: 屋頂防水隔熱 | C8: ='3_非主結構碳足跡(施工&廢棄&修繕)'!D14 -> 153419.2 | D8: ='3_非主結構碳足跡(施工&廢棄&修繕)'!E14 -> 767095.98 | E8: =C8/(C8+D8) -> 0.16666667 | F8: =D8/(C8+D8) -> 0.83333333
B9: 室內地坪 | C9: ='3_非主結構碳足跡(施工&廢棄&修繕)'!D15 -> 1797338.9 | D9: ='3_非主結構碳足跡(施工&廢棄&修繕)'!E15 -> 547780.12 | E9: =C9/(C9+D9) -> 0.76641692 | F9: =D9/(C9+D9) -> 0.23358308
B10: 戶外地坪 | C10: ='3_非主結構碳足跡(施工&廢棄&修繕)'!D16 -> 420257 | D10: ='3_非主結構碳足跡(施工&廢棄&修繕)'!E16 -> 196026.67 | E10: =C10/(C10+D10) -> 0.68192136 | F10: =D10/(C10+D10) -> 0.31807864
B12: kgCO2 | C12: 設計案新建 | D12: 設計案修繕 | E12: 基準案新建 | F12: 基準案修繕 | G12: 設計案新建+修繕
B13: 主結構體 | C13: =C3 -> 12554166 | D13: =D3 -> 0 | E13: ='3_非主結構碳足跡(施工&廢棄&修繕)'!D19 -> 15620641 | F13: ='3_非主結構碳足跡(施工&廢棄&修繕)'!E19 -> 0 | G13: =C13+D13 -> 12554166
B14: 外牆外裝 | C14: =C4 -> 1112683.9 | D14: =D4 -> 847656.32 | E14: ='3_非主結構碳足跡(施工&廢棄&修繕)'!D20 -> 1267583.9 | F14: ='3_非主結構碳足跡(施工&廢棄&修繕)'!E20 -> 888356.32 | G14: =C14+D14 -> 1960340.2
B15: 外窗 | C15: =C5 -> 234652.24 | D15: =D5 -> 0 | E15: ='3_非主結構碳足跡(施工&廢棄&修繕)'!D21 -> 234652.24 | F15: ='3_非主結構碳足跡(施工&廢棄&修繕)'!E21 -> 0 | G15: =C15+D15 -> 234652.24
B16: 不透光帷幕牆 | C16: =C6 -> 0 | D16: =D6 -> 0 | E16: ='3_非主結構碳足跡(施工&廢棄&修繕)'!D22 -> 0 | F16: ='3_非主結構碳足跡(施工&廢棄&修繕)'!E22 -> 0 | G16: =C16+D16 -> 0
B17: 內隔間 | C17: =C7 -> 310658 | D17: =D7 -> 0 | E17: ='3_非主結構碳足跡(施工&廢棄&修繕)'!D23 -> 516958.25 | F17: ='3_非主結構碳足跡(施工&廢棄&修繕)'!E23 -> 0 | G17: =C17+D17 -> 310658
B18: 屋頂防水隔熱 | C18: =C8 -> 153419.2 | D18: =D8 -> 767095.98 | E18: ='3_非主結構碳足跡(施工&廢棄&修繕)'!D24 -> 153419.2 | F18: ='3_非主結構碳足跡(施工&廢棄&修繕)'!E24 -> 767095.98 | G18: =C18+D18 -> 920515.17
B19: 室內地坪 | C19: =C9 -> 1797338.9 | D19: =D9 -> 547780.12 | E19: ='3_非主結構碳足跡(施工&廢棄&修繕)'!D25 -> 1797338.9 | F19: ='3_非主結構碳足跡(施工&廢棄&修繕)'!E25 -> 547780.12 | G19: =C19+D19 -> 2345119.1
B20: 戶外地坪 | C20: =C10 -> 420257 | D20: =D10 -> 196026.67 | E20: ='3_非主結構碳足跡(施工&廢棄&修繕)'!D26 -> 386512.44 | F20: ='3_非主結構碳足跡(施工&廢棄&修繕)'!E26 -> 162282.12 | G20: =C20+D20 -> 616283.67
B26: 分項工程新建與修繕碳足跡量比較圖
B43: 各分項工程新建與修繕碳排佔比構成圖
